Workbook

Sheet RESUMEN
A1: BALANCE | F1: PAGOS
A5: GASTOS | B5: MARZO | C5: ABRIL | D5: MAYO | F5: PAGO DOCENTES
A6: Alquiler | B6: 400000 | C6: 450000 | G6: 1HR Y MEDIA | H6: 1 HR
A7: Expensas | C7: 110080.3 | F7: HORA DOCENTE | G7: 14800 | H7: 9900
A8: Limpieza | C8: 64000
A9: Pago docentes | B9: =G14 -> 340300 | C9: =H14 -> 360000 | F9: PROFE | G9: MARZO | H9: ABRIL | I9: MAYO
A10: Publicidad | C10: 64000 | F10: Jime | G10: =$G$7*'DOCENTES Y CLASES '!B9 -> 44400 | H10: =$G$7*'DOCENTES Y CLASES '!C9 -> 44400 | I10: =$G$7*'DOCENTES Y CLASES '!D9 -> 44400
A11: Varios | B11: ='GASTOS VARIOS'!E1 -> 0 | C11: ='GASTOS VARIOS'!E2 -> 84538.85 | F11: Flor | G11: =$G$7*'DOCENTES Y CLASES '!B10 -> 0 | H11: =$G$7*'DOCENTES Y CLASES '!C10 -> 0 | I11: =$G$7*'DOCENTES Y CLASES '!D10 -> 0
A12: TOTAL GASTOS | B12: =SUM(B6:B11) -> 740300 | C12: =SUM(C6:C11) -> 1132619.2 | D12: =SUM(D6:D11) -> 0 | F12: Yaneiska | G12: =$G$7*'DOCENTES Y CLASES '!B11 -> 133200 | H12: =$G$7*'DOCENTES Y CLASES '!C11+'DOCENTES Y CLASES '!I9 -> 132400 | I12: =$G$7*'DOCENTES Y CLASES '!D11 -> 177600
A13: INGRESOS | B13: MARZO | C13: ABRIL | D13: MAYO | F13: Asly | G13: =$G$7*'DOCENTES Y CLASES '!B12+H7*'DOCENTES Y CLASES '!B13 -> 24700 | H13: =$G$7*'DOCENTES Y CLASES '!C12+H7*'DOCENTES Y CLASES '!C13 -> 143200 | I13: =$G$7*'DOCENTES Y CLASES '!D12+H7*'DOCENTES Y CLASES '!D13 -> 123500
A14: CLASES | B14: ='ALUMNAS '!M1 -> 656000 | C14: ='ALUMNAS '!N1 -> 741000 | D14: ='ALUMNAS '!O1 -> 75000 | F14: Totl pago docentes | G14: 340300 | H14: 360000 | I14: =SUM(I10:I13) -> 345500
A15: ALQUILER DE SALA | B15: ='ALQUILER DE SALA'!I1 -> 391000 | C15: ='ALQUILER DE SALA'!I2 -> 426000 | D15: ='ALQUILER DE SALA'!I3 -> 0
A16: TALLERES EXTRA | B16: 0 | F16: PAGO SOCIEDAD | N16: =17000*2 -> 34000
A17: PAGOS CXC
A18: TOTAL INGRESOS | B18: =SUM(B14:B17) -> 1047000 | C18: =SUM(C14:C17) -> 1167000 | D18: =SUM(D14:D17) -> 75000 | F18: PERSONAL | G18: MARZO | H18: ABRIL | I18: MAYO
A19: CUENTAS X COBRAR | B19: MARZO | C19: ABRIL | D19: MAYO | F19: Jime | G19: =IF($B$26<0,0,$B$26*0.7) -> 250600 | H19: =IF($C$26<0,0,$C$26*0.7) -> 57666.595 | I19: =IF($D$26<0,0,$B$26*0.7) -> 250600
A20: NINA | C20: 48000 | F20: Flor | G20: =IF($B$26<0,0,$B$26*0.15) -> 53700 | H20: =IF($C$26<0,0,$C$26*0.15) -> 12357.127 | I20: =IF($D$26<0,0,$B$26*0.7) -> 250600
F21: Yaneiska | G21: =IF($B$26<0,0,$B$26*0.15) -> 53700 | H21: =IF($C$26<0,0,$C$26*0.15) -> 12357.127 | I21: =IF($D$26<0,0,$B$26*0.7) -> 250600
A22: TOTAL CXC | B22: 51300 | C22: =SUM(C20:C21) -> 48000 | D22: =SUM(D20:D21) -> 0 | F22: Totl pago docentes | G22: =SUM(G19:G21) -> 358000 | H22: =SUM(H19:H21) -> 82380.85 | I22: =SUM(I19:I21) -> 751800
A24: ACTIVOS | B24: =B18+B22 -> 1098300 | C24: =C18+C22 -> 1215000 | D24: =D18+D22 -> 75000 | F24: PAGO TOTALES DEL ESTUDIO
A25: PASIVOS | B25: =+B12 -> 740300 | C25: =+C12 -> 1132619.2 | D25: =+D12 -> 0
A26: BALANCE | B26: =B24-B25 -> 358000 | C26: =C24-C25 -> 82380.85 | D26: =D24-D25 -> 75000 | F26: PERSONAL | G26: MARZO | H26: ABRIL | I26: MAYO
F27: Jime | G27: =G10+G19 -> 295000 | H27: =H10+H19 -> 102066.59 | I27: =I10+I19 -> 295000
F28: Flor | G28: =G11+G20 -> 53700 | H28: =H11+H20 -> 12357.127 | I28: =I11+I20 -> 250600
F29: Yaneiska | G29: =G12+G21 -> 186900 | H29: =H12+H21 -> 144757.13 | I29: =I12+I21 -> 428200 | K29: =H29-39000 -> 105757.13

Sheet GASTOS VARIOS
A1: GASTOS VARIOS | D1: TOTALS EPTIEMBRE | E1: =SUM(B7:B1390) -> 0
D2: TOTAL ABRIL | E2: =SUM(E7:E1390) -> 84538.85
D3: TOTAL MAYO | E3: =SUM(H7:H1390) -> 0
A5: MARZO | D5: ABRIL | G5: MAYO
A6: COMPRA | B6: COSTO | C6: TICKET | D6: COMPRA | E6: COSTO | F6: TICKET | G6: COMPRA | H6: COSTO | I6: TICKET
D7: luz | E7: 18158.85
D8: internet | E8: 43380
D9: Anita | E9: 15000
D10: impresión wifi | E10: 8000

Sheet DOCENTES Y CLASES 
A1: DOCENTES Y CLASES EJECUTADAS
A7: Profesora | B7: Horas Mensuales | G7: clase particular octubre
B8: MARZO | C8: ABRIL | D8: MAYO | H8: estudio | I8: yaneiska
A9: Jime | B9: 3 | C9: 3 | D9: 3 | G9: 20000 | H9: =G9*0.3 -> 6000 | I9: =G9*0.7 -> 14000
A10: Flor
A11: Yaneiska | B11: 9 | C11: 8 | D11: 12
A12: Asly 1 HR Y MEDIA | B12: 1 | C12: 7 | D12: 5
A13: Asly 1 HR | B13: 1 | C13: 4 | D13: 5 | F13: =+D11*13650 -> 163800

Sheet TALLERES 
A1: TALLERES
A4: NOMBRE | B4: Belly movs Y TALLER COREOGRAFICO DERBAKE | C4: total
A5: FECHA | C5: Ganancia
A7: FACILITADOR | C7: Pago
C8: Pago
A11: Incriptas
A12: Nombre | B12: Mail | C12: Pago

Sheet ALQUILER DE SALA
A1: ALQUILER DE SALA | E1: COSTO X HORA | H1: TOTALsep | I1: =SUM(D7:D1382) -> 391000
E2: ENTRE SEMANA | F2: 12000 | G2: 5800 | H2: TOTAL oct | I2: =SUM(H7:H1383) -> 426000
E3: Fin de semana | F3: 15000 | H3: TOTAL MAYO | I3: =SUM(L7:L1383) -> 0 | L3: =19200*2 -> 38400 | N3: =84000*2 -> 168000
N4: =N3-96000 -> 72000
A5: MARZO | E5: ABRIL | I5: MAYO
A6: NOMBRE | B6: ES | C6: FS | D6: TOTAL | E6: NOMBRE | F6: ES | G6: FS | H6: TOTAL | I6: NOMBRE | J6: DIA | K6: HORAS | L6: TOTAL
A7: Sofia | B7: 8 | D7: =B7*$F$2+C7*$F$3 -> 96000 | E7: Sofia | F7: 8 | H7: 72000
A8: Adriana | B8: 4 | C8: 5 | D8: =B8*$F$2+C8*$F$3 -> 123000 | E8: Adriana | F8: 4 | G8: 3 | H8: =F8*$F$2+G8*$F$3 -> 93000
A9: Lau | B9: 1 | D9: =B9*$F$2+C9*$F$3 -> 12000 | E9: Lau | F9: 5 | H9: =F9*$F$2+G9*$F$3 -> 60000
A10: Asly | B10: 16 | D10: =10000*B10 -> 160000 | E10: Asly | F10: =3*3 -> 9 | G10: 4 | H10: =10000*F10+12000*G10 -> 138000
D11: =B11*$F$2+C11*$F$3 -> 0 | E11: nina | F11: 4
D12: =B12*$F$2+C12*$F$3 -> 0 | E12: camila | F12: 4 | H12: =F2*F12 -> 48000 | N12: =31000*5 -> 155000
D13: =B13*$F$2+C13*$F$3 -> 0 | E13: gabriela | H13: =10000*F13 -> 0
D14: =B14*$F$2+C14*$F$3 -> 0 | E14: mariana | G14: 1 | H14: =G14*F3 -> 15000
D15: =B15*$F$2+C15*$F$3 -> 0 | H15: =10000*F15 -> 0
D16: =B16*$F$2+C16*$F$3 -> 0 | H16: =10000*F16 -> 0
D17: =B17*$F$2+C17*$F$3 -> 0 | H17: =10000*F17 -> 0
D18: =B18*$F$2+C18*$F$3 -> 0 | H18: =10000*F18 -> 0 | O18: 18:30 a 21:30
D19: =B19*$F$2+C19*$F$3 -> 0 | H19: =10000*F19 -> 0
D20: =B20*$F$2+C20*$F$3 -> 0 | H20: =10000*F20 -> 0 | O20: 3 hs
D21: =B21*$F$2+C21*$F$3 -> 0 | H21: =10000*F21 -> 0
D22: =B22*$F$2+C22*$F$3 -> 0 | H22: =10000*F22 -> 0
D23: =B23*$F$2+C23*$F$3 -> 0 | H23: =10000*F23 -> 0
D24: =B24*$F$2+C24*$F$3 -> 0 | H24: =10000*F24 -> 0
D25: =B25*$F$2+C25*$F$3 -> 0 | H25: =10000*F25 -> 0
D26: =B26*$F$2+C26*$F$3 -> 0 | H26: =10000*F26 -> 0
D27: =B27*$F$2+C27*$F$3 -> 0
D28: =B28*$F$2+C28*$F$3 -> 0
D29: =B29*$F$2+C29*$F$3 -> 0
D30: =B30*$F$2+C30*$F$3 -> 0
D31: =B31*$F$2+C31*$F$3 -> 0
D32: =B32*$F$2+C32*$F$3 -> 0
D33: =B33*$F$2+C33*$F$3 -> 0
D34: =B34*$F$2+C34*$F$3 -> 0
D35: =B35*$F$2+C35*$F$3 -> 0
D36: =B36*$F$2+C36*$F$3 -> 0
D37: =B37*$F$2+C37*$F$3 -> 0
D38: =B38*$F$2+C38*$F$3 -> 0
... D486: =B486*$F$2+C486*$F$3 -> 0

Sheet ALUMNAS 
A1: ALUMNAS Y ACTIVIDADES | H1: CLASE DE PRUEBA | I1: 15000 | L1: Ingreso | M1: 656000 | N1: =SUM(N2+N3) -> 741000 | O1: =SUM(O2+O3) -> 75000
L2: señas | M2: 0 | N2: =SUMIF(K6:K553,"SI",J6:J552) -> 75000 | O2: =SUMIF(K6:K553,"SI",J6:J552) -> 75000
M3: 656000 | N3: =SUMIF('ALUMNAS '!L6:L552, "SI",'ALUMNAS '!N6:N552) -> 666000 | O3: =SUMIF('ALUMNAS '!N6:N552, "SI",'ALUMNAS '!L6:L552) -> 0
A5: NOMBRE Y APELLIDO | B5: EDAD | C5: DIRECCIÓN | D5: MAIL | E5: TELEFONO | F5: COMBO | G5: Actividades | H5: Nivel ddv | I5: DOCENTE | J5: PRUEBA | K5: ¿PAGO SEÑA? | L5: PAGO | M5: DICIEMBRE | N5: OCTUBRE | O5: NOVIEMBRE
A6: Paula Alejandra Caceres | B6: 33 | C6: Belaustegui 4226 1D, Floresta, CABA | D6: paucaceres27@gmail.com | E6: 1126392925 | F6: CLASES 1 vez | G6: Danza Arabe | H6: Avanzado | I6: =IF(F6="","",IF(F6="Tecnicatura en composición coreográfica en ddv fusión","Jime",CONCATENATE(VLOOKUP(G6,OPCIONES!D:E,2,0),VLOOKUP(H6,OPCIONES!$G$2:$H$8,2,0)))) -> Flor | J6: =$I$1 -> 15000 | K6: NO | L6: NO | M6: 39000 | N6: =IF(F6="","",VLOOKUP(F6,OPCIONES!A:B,2,0)) -> 39000 | O6: =IF(F6="","",VLOOKUP(F6,OPCIONES!A:B,2,0)) -> 39000
A7: Camila Tomassetti | B7: 29 | C7: Mariano Acha 2820 1C. CABA | D7: cameela@live.com.ar | E7: 1168714794 | F7: CLASES 1 vez | G7: NO APLICA | H7: Intermedio/Avanzado | I7: =IF(F7="","",IF(F7="Tecnicatura en composición coreográfica en ddv fusión","Jime",CONCATENATE(VLOOKUP(G7,OPCIONES!D:E,2,0),VLOOKUP(H7,OPCIONES!$G$2:$H$8,2,0)))) -> Yaneiska | J7: =$I$1 -> 15000 | K7: NO | L7: SI | M7: 39000 | N7: =IF(F7="","",VLOOKUP(F7,OPCIONES!A:B,2,0)) -> 39000 | O7: =IF(F7="","",VLOOKUP(F7,OPCIONES!A:B,2,0)) -> 39000
A8: Maria Cecilia Tomasini | B8: 68 | C8: Jufre 250 piso 12 A | D8: tetraktys1234@gmail.com | E8: 1151242097 | F8: CLASES 2 veces | G8: Chinchines y tribal | H8: NO APLICA | I8: =IF(F8="","",IF(F8="Tecnicatura en composición coreográfica en ddv fusión","Jime",CONCATENATE(VLOOKUP(G8,OPCIONES!D:E,2,0),VLOOKUP(H8,OPCIONES!$G$2:$H$8,2,0)))) -> Asly | J8: =$I$1 -> 15000 | K8: NO | L8: NO | M8: 49000 | N8: =IF(F8="","",VLOOKUP(F8,OPCIONES!A:B,2,0)) -> 49000 | O8: =IF(F8="","",VLOOKUP(F8,OPCIONES!A:B,2,0)) -> 49000
A9: Camil Camarero | B9: 29 | C9: B. F. Moreno 1828 | D9: camilcamarero@gmail.com | E9: 1135796676 | F9: CLASES 2 veces | G9: Chinchines y tribal | H9: Intermedio/Avanzado | I9: =IF(F9="","",IF(F9="Tecnicatura en composición coreográfica en ddv fusión","Jime",CONCATENATE(VLOOKUP(G9,OPCIONES!D:E,2,0),VLOOKUP(H9,OPCIONES!$G$2:$H$8,2,0)))) -> AslyYaneiska | J9: =$I$1 -> 15000 | K9: NO | L9: SI | M9: 49000 | N9: =IF(F9="","",VLOOKUP(F9,OPCIONES!A:B,2,0)) -> 49000 | O9: =IF(F9="","",VLOOKUP(F9,OPCIONES!A:B,2,0)) -> 49000
A10: Lola montalban | B10: 29 | C10: Paysandu 2095 | D10: lolamontalban.psi@gmail.com | E10: 11 6754-8732 | F10: CLASES 1 vez | G10: Danza Arabe | H10: Intermedio/Avanzado | I10: =IF(F10="","",IF(F10="Tecnicatura en composición coreográfica en ddv fusión","Jime",CONCATENATE(VLOOKUP(G10,OPCIONES!D:E,2,0),VLOOKUP(H10,OPCIONES!$G$2:$H$8,2,0)))) -> Yaneiska | J10: =$I$1 -> 15000 | K10: NO | L10: NO | M10: 39000 | N10: =IF(F10="","",VLOOKUP(F10,OPCIONES!A:B,2,0)) -> 39000 | O10: =IF(F10="","",VLOOKUP(F10,OPCIONES!A:B,2,0)) -> 39000
A11: Paulina Soledad Puglia | B11: 46 | C11: Ciudadela 3795 parque leloir | D11: pp.estilistaunisex@hotmail.com | E11: 1162733885 | F11: Profesorado danza del vientre intensivo (2 veces por semana+teóricos) | G11: Danza Arabe | H11: Principiante | I11: =IF(F11="","",IF(F11="Tecnicatura en composición coreográfica en ddv fusión","Jime",CONCATENATE(VLOOKUP(G11,OPCIONES!D:E,2,0),VLOOKUP(H11,OPCIONES!$G$2:$H$8,2,0)))) -> Yaneiska | J11: =$I$1 -> 15000 | K11: NO | L11: SI | M11: 59000 | N11: =IF(F11="","",VLOOKUP(F11,OPCIONES!A:B,2,0)) -> 59000 | O11: =IF(F11="","",VLOOKUP(F11,OPCIONES!A:B,2,0)) -> 59000
A12: Maria Celeste Gomez | B12: 19 | C12: Calderón de la Barca 1750 | D12: macelestegomez.z@gmail.com | E12: 11 3686-0499 | F12: Profesorado danza del vientre intensivo (2 veces por semana+teóricos) | G12: Danza Arabe | H12: Principiante | I12: =IF(F12="","",IF(F12="Tecnicatura en composición coreográfica en ddv fusión","Jime",CONCATENATE(VLOOKUP(G12,OPCIONES!D:E,2,0),VLOOKUP(H12,OPCIONES!$G$2:$H$8,2,0)))) -> Yaneiska | J12: =$I$1 -> 15000 | K12: NO | L12: SI | M12: 59000 | N12: =IF(F12="","",VLOOKUP(F12,OPCIONES!A:B,2,0)) -> 59000 | O12: =IF(F12="","",VLOOKUP(F12,OPCIONES!A:B,2,0)) -> 59000
A13: Elizabeth | E13: 1135041213 | F13: CLASES 1 vez | G13: Chinchines y tribal | H13: NO APLICA | I13: =IF(F13="","",IF(F13="Tecnicatura en composición coreográfica en ddv fusión","Jime",CONCATENATE(VLOOKUP(G13,OPCIONES!D:E,2,0),VLOOKUP(H13,OPCIONES!$G$2:$H$8,2,0)))) -> Asly | J13: =$I$1 -> 15000 | K13: NO | L13: SI | M13: 49000 | N13: =IF(F13="","",VLOOKUP(F13,OPCIONES!A:B,2,0)) -> 39000 | O13: =IF(F13="","",VLOOKUP(F13,OPCIONES!A:B,2,0)) -> 39000
A14: Yaneiska Belandria | B14: 33 | C14: Blanco encalada 5058 | D14: yaneiskab@gmail.com | E14: 1156350403 | F14: CLASES 1 vez | G14: Perfeccionamiento Danza del vientre | H14: NO APLICA | I14: =IF(F14="","",IF(F14="Tecnicatura en composición coreográfica en ddv fusión","Jime",CONCATENATE(VLOOKUP(G14,OPCIONES!D:E,2,0),VLOOKUP(H14,OPCIONES!$G$2:$H$8,2,0)))) -> Jime, | J14: =$I$1 -> 15000 | K14: NO | L14: SI | M14: 39000 | N14: =IF(F14="","",VLOOKUP(F14,OPCIONES!A:B,2,0)) -> 39000 | O14: =IF(F14="","",VLOOKUP(F14,OPCIONES!A:B,2,0)) -> 39000
A15: Gabriela Cipolla | B15: 46 | C15: Hidalgo 1264 B | D15: cipollag@hotmail.com | E15: 1136765517 | F15: Profesorado danza del vientre intensivo (2 veces por semana+teóricos) | G15: Danza Arabe | H15: Principiante/Intermedio | I15: =IF(F15="","",IF(F15="Tecnicatura en composición coreográfica en ddv fusión","Jime",CONCATENATE(VLOOKUP(G15,OPCIONES!D:E,2,0),VLOOKUP(H15,OPCIONES!$G$2:$H$8,2,0)))) -> Yaneiska | J15: =$I$1 -> 15000 | K15: NO | L15: SI | M15: 59000 | N15: =IF(F15="","",VLOOKUP(F15,OPCIONES!A:B,2,0)) -> 59000 | O15: =IF(F15="","",VLOOKUP(F15,OPCIONES!A:B,2,0)) -> 59000
A16: Maria Laura Sosa Ocanto | B16: 37 | C16: Lavalleja 263 | D16: marialaurasosaocanto@gmail.com | E16: 3516138932 | F16: CLASES 2 veces | G16: Danza Arabe | H16: Principiante/Intermedio | I16: =IF(F16="","",IF(F16="Tecnicatura en composición coreográfica en ddv fusión","Jime",CONCATENATE(VLOOKUP(G16,OPCIONES!D:E,2,0),VLOOKUP(H16,OPCIONES!$G$2:$H$8,2,0)))) -> Yaneiska | J16: =$I$1 -> 15000 | K16: NO | L16: SI | M16: 49000 | N16: =IF(F16="","",VLOOKUP(F16,OPCIONES!A:B,2,0)) -> 49000 | O16: =IF(F16="","",VLOOKUP(F16,OPCIONES!A:B,2,0)) -> 49000
A17: Florencia Maria Rodriguez | B17: 27 | C17: Cachi 890 | D17: flo3214e@gmail.com | E17: 1127687922 | F17: CLASES 1 vez | G17: Danza Arabe | H17: Principiante | I17: =IF(F17="","",IF(F17="Tecnicatura en composición coreográfica en ddv fusión","Jime",CONCATENATE(VLOOKUP(G17,OPCIONES!D:E,2,0),VLOOKUP(H17,OPCIONES!$G$2:$H$8,2,0)))) -> Yaneiska | J17: =$I$1 -> 15000 | K17: NO | L17: NO | M17: 39000 | N17: =IF(F17="","",VLOOKUP(F17,OPCIONES!A:B,2,0)) -> 39000 | O17: =IF(F17="","",VLOOKUP(F17,OPCIONES!A:B,2,0)) -> 39000
A18: Lorena | F18: CLASES 1 vez | G18: Danza Arabe | H18: Principiante | I18: =IF(F18="","",IF(F18="Tecnicatura en composición coreográfica en ddv fusión","Jime",CONCATENATE(VLOOKUP(G18,OPCIONES!D:E,2,0),VLOOKUP(H18,OPCIONES!$G$2:$H$8,2,0)))) -> Yaneiska | J18: =$I$1 -> 15000 | K18: SI | L18: NO | M18: 39000 | N18: =IF(F18="","",VLOOKUP(F18,OPCIONES!A:B,2,0)) -> 39000 | O18: =IF(F18="","",VLOOKUP(F18,OPCIONES!A:B,2,0)) -> 39000
A19: Susana | F19: CLASES 1 vez | G19: Danza Arabe | H19: Principiante | I19: =IF(F19="","",IF(F19="Tecnicatura en composición coreográfica en ddv fusión","Jime",CONCATENATE(VLOOKUP(G19,OPCIONES!D:E,2,0),VLOOKUP(H19,OPCIONES!$G$2:$H$8,2,0)))) -> Yaneiska | J19: =$I$1 -> 15000 | K19: NO | L19: si | M19: 30000 | N19: =IF(F19="","",VLOOKUP(F19,OPCIONES!A:B,2,0)) -> 39000 | O19: =IF(F19="","",VLOOKUP(F19,OPCIONES!A:B,2,0)) -> 39000
A20: FLOR DE LA FUENTE | F20: CLASES 1 vez | G20: Perfeccionamiento | H20: NO APLICA | I20: =IF(F20="","",IF(F20="Tecnicatura en composición coreográfica en ddv fusión","Jime",CONCATENATE(VLOOKUP(G20,OPCIONES!D:E,2,0),VLOOKUP(H20,OPCIONES!$G$2:$H$8,2,0)))) -> Jime, | J20: =$I$1 -> 15000 | K20: NO | L20: SI | N20: =IF(F20="","",VLOOKUP(F20,OPCIONES!A:B,2,0)) -> 39000 | O20: =IF(F20="","",VLOOKUP(F20,OPCIONES!A:B,2,0)) -> 39000
A21: ROSA | F21: CLASES 1 vez | G21: Perfeccionamiento | H21: NO APLICA | I21: =IF(F21="","",IF(F21="Tecnicatura en composición coreográfica en ddv fusión","Jime",CONCATENATE(VLOOKUP(G21,OPCIONES!D:E,2,0),VLOOKUP(H21,OPCIONES!$G$2:$H$8,2,0)))) -> Jime, | J21: =$I$1 -> 15000 | K21: NO | L21: SI | N21: =IF(F21="","",VLOOKUP(F21,OPCIONES!A:B,2,0)) -> 39000 | O21: =IF(F21="","",VLOOKUP(F21,OPCIONES!A:B,2,0)) -> 39000
A22: Agostina | F22: CLASES 1 vez | G22: Perfeccionamiento | H22: NO APLICA | I22: =IF(F22="","",IF(F22="Tecnicatura en composición coreográfica en ddv fusión","Jime",CONCATENATE(VLOOKUP(G22,OPCIONES!D:E,2,0),VLOOKUP(H22,OPCIONES!$G$2:$H$8,2,0)))) -> Jime, | J22: =$I$1 -> 15000 | K22: si | L22: no | N22: =IF(F22="","",VLOOKUP(F22,OPCIONES!A:B,2,0)) -> 39000 | O22: =IF(F22="","",VLOOKUP(F22,OPCIONES!A:B,2,0)) -> 39000
A23: Liliana | F23: CLASES 1 vez | G23: Perfeccionamiento | H23: NO APLICA | I23: =IF(F23="","",IF(F23="Tecnicatura en composición coreográfica en ddv fusión","Jime",CONCATENATE(VLOOKUP(G23,OPCIONES!D:E,2,0),VLOOKUP(H23,OPCIONES!$G$2:$H$8,2,0)))) -> Jime, | J23: =$I$1 -> 15000 | K23: NO | L23: SI | N23: =IF(F23="","",VLOOKUP(F23,OPCIONES!A:B,2,0)) -> 39000
A24: jeza | F24: CLASES 2 veces | G24: Danza Arabe | H24: Multinivel | I24: =IF(F24="","",IF(F24="Tecnicatura en composición coreográfica en ddv fusión","Jime",CONCATENATE(VLOOKUP(G24,OPCIONES!D:E,2,0),VLOOKUP(H24,OPCIONES!$G$2:$H$8,2,0)))) -> Yaneiska | J24: =$I$1 -> 15000 | K24: NO | L24: SI | N24: 30000
A25: victoria erazu | F25: CLASES 1 vez | G25: Danza Arabe | H25: Principiante | I25: =IF(F25="","",IF(F25="Tecnicatura en composición coreográfica en ddv fusión","Jime",CONCATENATE(VLOOKUP(G25,OPCIONES!D:E,2,0),VLOOKUP(H25,OPCIONES!$G$2:$H$8,2,0)))) -> Yaneiska | J25: =$I$1 -> 15000 | K25: si | L25: no | N25: =IF(F25="","",VLOOKUP(F25,OPCIONES!A:B,2,0)) -> 39000
A26: Belu | F26: CLASES 1 vez | G26: Danza Arabe | H26: Principiante | I26: =IF(F26="","",IF(F26="Tecnicatura en composición coreográfica en ddv fusión","Jime",CONCATENATE(VLOOKUP(G26,OPCIONES!D:E,2,0),VLOOKUP(H26,OPCIONES!$G$2:$H$8,2,0)))) -> Yaneiska | J26: =$I$1 -> 15000 | K26: si | L26: no | N26: =IF(F26="","",VLOOKUP(F26,OPCIONES!A:B,2,0)) -> 39000
A27: jes | F27: CLASES 1 vez | G27: Perfeccionamiento | H27: NO APLICA | I27: =IF(F27="","",IF(F27="Tecnicatura en composición coreográfica en ddv fusión","Jime",CONCATENATE(VLOOKUP(G27,OPCIONES!D:E,2,0),VLOOKUP(H27,OPCIONES!$G$2:$H$8,2,0)))) -> Jime, | J27: =$I$1 -> 15000 | K27: si | L27: no | N27: =IF(F27="","",VLOOKUP(F27,OPCIONES!A:B,2,0)) -> 39000
A28: kayla | F28: CLASES 2 veces | G28: Chinchines y tribal | H28: NO APLICA | I28: =IF(F28="","",IF(F28="Tecnicatura en composición coreográfica en ddv fusión","Jime",CONCATENATE(VLOOKUP(G28,OPCIONES!D:E,2,0),VLOOKUP(H28,OPCIONES!$G$2:$H$8,2,0)))) -> Asly | J28: =$I$1 -> 15000 | K28: NO | L28: SI | N28: =IF(F28="","",VLOOKUP(F28,OPCIONES!A:B,2,0)) -> 49000
A29: ximena | F29: CLASES 1 vez | G29: chinchines | H29: NO APLICA | I29: =IF(F29="","",IF(F29="Tecnicatura en composición coreográfica en ddv fusión","Jime",CONCATENATE(VLOOKUP(G29,OPCIONES!D:E,2,0),VLOOKUP(H29,OPCIONES!$G$2:$H$8,2,0)))) -> Asly | J29: =$I$1 -> 15000 | K29: NO | L29: SI | N29: =IF(F29="","",VLOOKUP(F29,OPCIONES!A:B,2,0)) -> 39000
I30: =IF(F30="","",IF(F30="Tecnicatura en composición coreográfica en ddv fusión","Jime",CONCATENATE(VLOOKUP(G30,OPCIONES!D:E,2,0),VLOOKUP(H30,OPCIONES!$G$2:$H$8,2,0)))) | J30: =$I$1 -> 15000 | K30: NO | L30: SI | N30: =IF(F30="","",VLOOKUP(F30,OPCIONES!A:B,2,0))
I31: =IF(F31="","",IF(F31="Tecnicatura en composición coreográfica en ddv fusión","Jime",CONCATENATE(VLOOKUP(G31,OPCIONES!D:E,2,0),VLOOKUP(H31,OPCIONES!$G$2:$H$8,2,0)))) | J31: =$I$1 -> 15000 | K31: NO | L31: SI | N31: =IF(F31="","",VLOOKUP(F31,OPCIONES!A:B,2,0))
I32: =IF(F32="","",IF(F32="Tecnicatura en composición coreográfica en ddv fusión","Jime",CONCATENATE(VLOOKUP(G32,OPCIONES!D:E,2,0),VLOOKUP(H32,OPCIONES!$G$2:$H$8,2,0)))) | J32: =$I$1 -> 15000 | K32: NO | L32: SI | N32: =IF(F32="","",VLOOKUP(F32,OPCIONES!A:B,2,0))
I33: =IF(F33="","",IF(F33="Tecnicatura en composición coreográfica en ddv fusión","Jime",CONCATENATE(VLOOKUP(G33,OPCIONES!D:E,2,0),VLOOKUP(H33,OPCIONES!$G$2:$H$8,2,0)))) | J33: =$I$1 -> 15000 | K33: NO | L33: SI | N33: =IF(F33="","",VLOOKUP(F33,OPCIONES!A:B,2,0))
I34: =IF(F34="","",IF(F34="Tecnicatura en composición coreográfica en ddv fusión","Jime",CONCATENATE(VLOOKUP(G34,OPCIONES!D:E,2,0),VLOOKUP(H34,OPCIONES!$G$2:$H$8,2,0)))) | J34: =$I$1 -> 15000 | K34: NO | L34: SI | N34: =IF(F34="","",VLOOKUP(F34,OPCIONES!A:B,2,0))
I35: =IF(F35="","",IF(F35="Tecnicatura en composición coreográfica en ddv fusión","Jime",CONCATENATE(VLOOKUP(G35,OPCIONES!D:E,2,0),VLOOKUP(H35,OPCIONES!$G$2:$H$8,2,0)))) | J35: =$I$1 -> 15000 | K35: NO | L35: SI | N35: =IF(F35="","",VLOOKUP(F35,OPCIONES!A:B,2,0))
I36: =IF(F36="","",IF(F36="Tecnicatura en composición coreográfica en ddv fusión","Jime",CONCATENATE(VLOOKUP(G36,OPCIONES!D:E,2,0),VLOOKUP(H36,OPCIONES!$G$2:$H$8,2,0)))) | J36: =$I$1 -> 15000 | K36: NO | L36: SI | N36: =IF(F36="","",VLOOKUP(F36,OPCIONES!A:B,2,0))
I37: =IF(F37="","",IF(F37="Tecnicatura en composición coreográfica en ddv fusión","Jime",CONCATENATE(VLOOKUP(G37,OPCIONES!D:E,2,0),VLOOKUP(H37,OPCIONES!$G$2:$H$8,2,0)))) | J37: =$I$1 -> 15000 | K37: NO | L37: SI | N37: =IF(F37="","",VLOOKUP(F37,OPCIONES!A:B,2,0))
I38: =IF(F38="","",IF(F38="Tecnicatura en composición coreográfica en ddv fusión","Jime",CONCATENATE(VLOOKUP(G38,OPCIONES!D:E,2,0),VLOOKUP(H38,OPCIONES!$G$2:$H$8,2,0)))) | J38: =$I$1 -> 15000 | K38: NO | L38: SI | N38: =IF(F38="","",VLOOKUP(F38,OPCIONES!A:B,2,0))
I39: =IF(F39="","",IF(F39="Tecnicatura en composición coreográfica en ddv fusión","Jime",CONCATENATE(VLOOKUP(G39,OPCIONES!D:E,2,0),VLOOKUP(H39,OPCIONES!$G$2:$H$8,2,0)))) | J39: =$I$1 -> 15000 | K39: NO | L39: SI | N39: =IF(F39="","",VLOOKUP(F39,OPCIONES!A:B,2,0))
I40: =IF(F40="","",IF(F40="Tecnicatura en composición coreográfica en ddv fusión","Jime",CONCATENATE(VLOOKUP(G40,OPCIONES!D:E,2,0),VLOOKUP(H40,OPCIONES!$G$2:$H$8,2,0)))) | J40: =$I$1 -> 15000 | K40: NO | L40: SI | N40: =IF(F40="","",VLOOKUP(F40,OPCIONES!A:B,2,0))
I41: =IF(F41="","",IF(F41="Tecnicatura en composición coreográfica en ddv fusión","Jime",CONCATENATE(VLOOKUP(G41,OPCIONES!D:E,2,0),VLOOKUP(H41,OPCIONES!$G$2:$H$8,2,0)))) | J41: =$I$1 -> 15000 | K41: NO | L41: SI | N41: =IF(F41="","",VLOOKUP(F41,OPCIONES!A:B,2,0))
...

Sheet Hoja2

Sheet ARANCELES
A1: ARANCELES | E1: =17000*2 -> 34000 | F1: =27500+17000 -> 44500 | G1: =19500+26500 -> 46000 | H1: =26500+26500 -> 53000 | I1: =18500+38000 -> 56500
I2: =19500+38000 -> 57500
A3: FORMACI+A3:D24ONES | B3: COSTO | G3: =19500+18500 -> 38000 | H3: =26500+18500 -> 45000
A4: Profesorado danza del vientre básico (una vez x semana+teórico mensual) | B4: 47000 | E4: =+B4*1.2 -> 56400 | F4: 47000
A5: Profesorado danza del vientre intensivo (2 veces por semana+teóricos) | B5: 59000 | E5: =+B5*1.2 -> 70800 | F5: 59000
A6: Tecnicatura en composición coreográfica en ddv fusión | E6: 43000 | F6: 43000
A8: COMBOS FORMACIONES | B8: 1 actividad | C8: 2 actividades | D8: 3 actividades
A9: Profesorado básico | B9: 50000 | C9: 61000 | D9: 72000 | G9: =+F4*2 -> 94000
A10: Profesorado intensivo | B10: 61000 | C10: 72000 | D10: 83000
A11: Tecnicatura | B11: 45000 | C11: 55000 | D11: 65000
A13: PROFESORADO + TECNICATURA | B13: COSTO
A14: Profesorado Básico +Tecnicatura | B14: 50000
A15: Profesorado Intensivo +Tecnicatura | B15: 60000
A17: CLASES | B17: 1 vez | C17: 2 veces | D17: 3 veces
A18: Pilates mat | B18: 39000 | C18: 49000 | D18: 70000 | F18: 39000 | G18: 49000 | H18: 70000
A19: Yoga y elongación
A20: Danza del vientre
A21: perfeccionamiento danza del vientre
A22: Perfeccionamiento para bailarinas+lab de composición
A23: Danza teatro
A24: Perfecc. Téc. y expresivo para bailarinas + lab. de composición coreográfica
A26: CLASE PARTICULAR | B26: 20000
C28: =+B18*1.1 -> 42900
E29: =10000*1.2 -> 12000
E30: =+E29*3 -> 36000

Sheet OPCIONES
A2: =ARANCELES!A4 -> Profesorado danza del vientre básico (una vez x semana+teórico mensual) | B2: =ARANCELES!B4 -> 47000 | D2: Pilates | E2: Yaneiska, | G2: Principiante | H2: Yaneiska
A3: =ARANCELES!A5 -> Profesorado danza del vientre intensivo (2 veces por semana+teóricos) | B3: =ARANCELES!B5 -> 59000 | D3: Yoga | E3: Jime, | G3: Principiante/Intermedio | H3: Yaneiska
A4: =ARANCELES!A6 -> Tecnicatura en composición coreográfica en ddv fusión | B4: =ARANCELES!B6 -> 0 | D4: Perfeccionamiento | E4: Jime, | G4: Intermedio | H4: Yaneiska
A5: =CONCATENATE(ARANCELES!A9," ",ARANCELES!B8) -> Profesorado básico 1 actividad | B5: =ARANCELES!B9 -> 50000 | D5: Instructorado | E5: Jime, | G5: Intermedio/Avanzado | H5: Yaneiska
A6: =CONCATENATE(ARANCELES!A9," ",ARANCELES!C8) -> Profesorado básico 2 actividades | B6: =ARANCELES!C9 -> 61000 | D6: Psicomotricidad | E6: Jime, | G6: Avanzado | H6: Flor
A7: =CONCATENATE(ARANCELES!A9," ",ARANCELES!D8) -> Profesorado básico 3 actividades | B7: =ARANCELES!D9 -> 72000 | D7: Pilates, Yoga, Arabe, Perfeccionamiento,Psicomotricidad, Danza teatro | E7: Yaneiska, Jime, | G7: Multinivel | H7: Yaneiska
A8: =CONCATENATE(ARANCELES!A10," ",ARANCELES!B8) -> Profesorado intensivo 1 actividad | B8: =ARANCELES!B10 -> 61000 | D8: Pilates y Danza Arabe | E8: Yaneiska, | G8: NO APLICA
A9: =CONCATENATE(ARANCELES!A10," ",ARANCELES!C8) -> Profesorado intensivo 2 actividades | B9: =ARANCELES!C10 -> 72000 | D9: Pilates y Perfeccionamiento | E9: Yaneiska, Jime,
A10: =CONCATENATE(ARANCELES!A10," ",ARANCELES!D8) -> Profesorado intensivo 3 actividades | B10: =ARANCELES!D10 -> 83000 | D10: Pilates y Psicomotricidad | E10: Yaneiska, Jime,
A11: =CONCATENATE(ARANCELES!A11," ",ARANCELES!B8) -> Tecnicatura 1 actividad | B11: =ARANCELES!B11 -> 45000 | D11: Pilates y Danza Teatro | E11: Yaneiska, Jime,
A12: =CONCATENATE(ARANCELES!A11," ",ARANCELES!C8) -> Tecnicatura 2 actividades | B12: =ARANCELES!C11 -> 55000 | D12: Yoga y Danza Arabe | E12: Yaneiska,
A13: =CONCATENATE(ARANCELES!A11," ",ARANCELES!D8) -> Tecnicatura 3 actividades | B13: =ARANCELES!D11 -> 65000 | D13: Yoga y Perfeccionamiento | E13: Jime,
A14: =ARANCELES!A14 -> Profesorado Básico +Tecnicatura | B14: =ARANCELES!B14 -> 50000 | D14: Yoga y Psicomotricidad | E14: Jime,
A15: =ARANCELES!A15 -> Profesorado Intensivo +Tecnicatura | B15: =ARANCELES!B15 -> 60000 | D15: Yogay Danza Teatro | E15: Jime,
A16: =CONCATENATE(ARANCELES!A17," ",ARANCELES!B17) -> CLASES 1 vez | B16: =ARANCELES!B18 -> 39000 | D16: Danza Arabe y Perfeccionamiento | E16: Jime, | G16: Clase de prueba | H16: =15000/4 -> 3750
A17: =CONCATENATE(ARANCELES!A17," ",ARANCELES!C17) -> CLASES 2 veces | B17: =ARANCELES!C18 -> 49000 | D17: Danza Arabe y Psicomotricidad | E17: Jime,
A18: =CONCATENATE(ARANCELES!A17," ",ARANCELES!D17) -> CLASES 3 veces | B18: =ARANCELES!D18 -> 70000 | D18: Danza Arabe y Danza Teatro | E18: Jime,
A19: Clase particular | B19: 18000 | D19: Perfeccionamiento y Psicomotricidad | E19: Jime,
D20: Tecnicatura, Pilates, Yoga, Arabe, Perfeccionamiento,Psicomotricidad, Danza teatro | E20: Jime, Yaneiska,
D21: Tecnicatura y Danza Arabe | E21: Jime,
D22: Tecnicatura y Perfeccionamiento | E22: Jime,
D23: Tecnicatura y Psicomotricidad | E23: Jime,
D24: Tecnicatura y Danza Teatro | E24: Jime,
D25: Tecnicatura y Pilates | E25: Jime, Yaneiska,
D26: Danza Arabe
D27: Danza teatro | E27: Jime
D28: Tribal | E28: Asly
D29: Perfeccionamiento Danza del vientre | E29: Jime,
D30: Perfeccionamiento Danza del vientre y Arabe | E30: Jime,
D31: NO APLICA
D32: Clase particular | E32: Yane
D33: Chinchines y tribal | E33: Asly
D34: chinchines | E34: Asly

Sheet PUBLICIDAD
A1: PUBLICIDAD
A3: FEBRERO | G3: MARZO | M3: ABRIL | Q3: JUNIO
B4: Facebk Q62j43llm Q62j Usd 2,09 921002e | D4: 2.09 | G4: 45362 | H4: Facebk *fezqnzbmm2 | J4: 20.88 | L4: 45380 | M4: Facebk *acszy4llm2 Usd 32,39 263820e | O4: 32.39 | Q4: 45442 | R4: Facebk *ntxdp6qtg2 Usd 2,55 652582e | T4: 2.55
A5: 45328 | B5: Facebk *r274fybmm2 Usd 1,83 092096e | D5: 1.83 | G5: 45360 | H5: Facebk *49geb4llm2 | J5: 14.91 | L5: 45390 | M5: Facebk *a4st73ylm2 Usd 31,36 227170e | O5: 31.36 | Q5: 45443 | R5: Facebk *u39lq6qtg2 Usd 2,55 610956e | T5: 2.55
A6: 45329 | B6: Facebk *tsxryyplm2 Usd 2,74 309407e | D6: 2.74 | G6: 45359 | H6: Facebk *xlzn94llm2 | J6: 6.44 | L6: 45398 | M6: Facebk *4zmtu4qtg2 Usd 1,75 624138e | O6: 1.75 | Q6: 45443 | R6: Facebk *uv86w88tg2 Usd 2,54 567361e | T6: 2.54
A7: 45329 | B7: Facebk *7nsz72lmm2 Usd 2,74 632585e | D7: 2.74 | G7: 45359 | H7: Facebk *4939n24mm2 | J7: 4.97 | L7: 45398 | M7: Facebk *km7vb3usg2 Usd 1,75 162052e | O7: 1.75 | Q7: 45446 | R7: Facebk *cuk6a7ctg2 Usd 3,95 853545e | T7: 3.95
A8: 45330 | B8: Facebk *lcbchybmm2 Usd 2,57 310110e | D8: 2.57 | G8: 45357 | H8: Facebk *h76p728mm2 Usd 14,94 093111e | J8: 14.94 | L8: 45399 | M8: Facebk *uja6278tg2 Usd 1,95 853487e | O8: 1.95 | Q8: 45447 | R8: Facebk *lsbqv6qtg2 Usd 1,42 262786e | T8: 1.42
A9: 45330 | B9: Facebk *hr9473llm2 Usd 2,74 754172e | D9: 2.74 | G9: 45352 | H9: Facebk *rp7zd24mm2 | J9: 10.88 | L9: 45399 | M9: Facebk *v39tz68tg2 Usd 1,75 656286e | O9: 1.75 | Q9: 45461 | R9: Facebk *8r2m764tg2 Usd 3,92 056169e | T9: 3.92
A10: 45331 | B10: Facebk *4mgh3ztlm2 Usd 4,25 324495e | D10: 4.25 | J10: =SUM(J4:J9) -> 73.02 | K10: =J10*1000 -> 73020 | O10: =SUM(O4:O9) -> 70.95 | Q10: 45462 | R10: Facebk *uvj826usg2 Usd 5,58 544418e | T10: 5.58
A11: 45331 | B11: Facebk *ffdd2zplm2 Usd 4,25 622163e | D11: 4.25 | I11: Saldo a favor | J11: 18.52 | Q11: 45464 | R11: Facebk *qjpas5gtg2 Usd 8,36 708079e | T11: 8.36
A12: 45332 | B12: Facebk *49grkybmm2 Usd 6,08 641560e | D12: 6.08 | O12: =+O10*900 -> 63855 | T12: =SUM(T4:T11) -> 30.87
A13: 45333 | B13: Facebk *nscgpz3mm2 Usd 6,08 246003e | D13: 6.08 | I13: A pagar | J13: =J10-J11 -> 54.5 | S13: A favor: | T13: =100-O10 -> 29.05 | U13: =T13*1400 -> 40670
A14: 45338 | B14: Facebk *9smlsybmm2 Usd 9,08 964438e | D14: 9.08
A15: 45341 | B15: Facebk *m8bhezplm2 Usd 9,07 903185e | D15: 9.07 | S15: A Pagar | T15: =T12-T13 -> 1.82
A16: 45344 | B16: Facebk *ymdd424mm2 Usd 9,04 761972e | D16: 9.04
A17: 45349 | B17: Facebk *rpq8w3llm2 Usd 9,01 910124e | D17: 9.01
A18: 45350 | B18: Facebk *zdq2szxlm2 Usd 9,91 105211e | D18: 9.91
C19: total | D19: =SUM(D4:D18) -> 81.48 | J19: =J5+J6+J7+J8 -> 41.26
A21: Aporte de Jime | B21: 45358 | D21: 100
A23: saldo a favor | D23: =D21-D19 -> 18.52

Sheet Hoja1
A1: auspiciantes
G2: jg
A3: anita | E3: yaneiskabelandria | J3: yanebeladane
A4: talentos
A5: lady producciones
A6: winy
A7: juli
A8: ph.geralsepu
A9: creativanails
A10: arabia dance
A11: shurkan
A12: coffee danse
A13: shared
A14: nubia.danza
A15: romina ostellino
... A19: caderines.estefani
